Traceback (most recent call last):
  File "C:\Users\kelly\AppData\Local\Programs\Python\Python312\Lib\site-packages\urllib3\connectionpool.py", line 793, in urlopen
    response = self._make_request(
               ^^^^^^^^^^^^^^^^^^^
  File "C:\Users\kelly\AppData\Local\Programs\Python\Python312\Lib\site-packages\urllib3\connectionpool.py", line 537, in _make_request
    response = conn.getresponse()
               ^^^^^^^^^^^^^^^^^^
  File "C:\Users\kelly\AppData\Local\Programs\Python\Python312\Lib\site-packages\urllib3\connection.py", line 466, in getresponse
    httplib_response = super().getresponse()
                       ^^^^^^^^^^^^^^^^^^^^^
  File "C:\Users\kelly\AppData\Local\Programs\Python\Python312\Lib\http\client.py", line 1428, in getresponse
    response.begin()
  File "C:\Users\kelly\AppData\Local\Programs\Python\Python312\Lib\http\client.py", line 331, in begin
    version, status, reason = self._read_status()
                              ^^^^^^^^^^^^^^^^^^^
  File "C:\Users\kelly\AppData\Local\Programs\Python\Python312\Lib\http\client.py", line 300, in _read_status
    raise RemoteDisconnected("Remote end closed connection without"
http.client.RemoteDisconnected: Remote end closed connection without response

During handling of the above exception, another exception occurred:

Traceback (most recent call last):
  File "C:\Users\kelly\AppData\Local\Programs\Python\Python312\Lib\site-packages\requests\adapters.py", line 486, in send
    resp = conn.urlopen(
           ^^^^^^^^^^^^^
  File "C:\Users\kelly\AppData\Local\Programs\Python\Python312\Lib\site-packages\urllib3\connectionpool.py", line 847, in urlopen
    retries = retries.increment(
              ^^^^^^^^^^^^^^^^^^
  File "C:\Users\kelly\AppData\Local\Programs\Python\Python312\Lib\site-packages\urllib3\util\retry.py", line 470, in increment
    raise reraise(type(error), error, _stacktrace)
          ^^^^^^^^^^^^^^^^^^^^^^^^^^^^^^^^^^^^^^^^
  File "C:\Users\kelly\AppData\Local\Programs\Python\Python312\Lib\site-packages\urllib3\util\util.py", line 38, in reraise
    raise value.with_traceback(tb)
  File "C:\Users\kelly\AppData\Local\Programs\Python\Python312\Lib\site-packages\urllib3\connectionpool.py", line 793, in urlopen
    response = self._make_request(
               ^^^^^^^^^^^^^^^^^^^
  File "C:\Users\kelly\AppData\Local\Programs\Python\Python312\Lib\site-packages\urllib3\connectionpool.py", line 537, in _make_request
    response = conn.getresponse()
               ^^^^^^^^^^^^^^^^^^
  File "C:\Users\kelly\AppData\Local\Programs\Python\Python312\Lib\site-packages\urllib3\connection.py", line 466, in getresponse
    httplib_response = super().getresponse()
                       ^^^^^^^^^^^^^^^^^^^^^
  File "C:\Users\kelly\AppData\Local\Programs\Python\Python312\Lib\http\client.py", line 1428, in getresponse
    response.begin()
  File "C:\Users\kelly\AppData\Local\Programs\Python\Python312\Lib\http\client.py", line 331, in begin
    version, status, reason = self._read_status()
                              ^^^^^^^^^^^^^^^^^^^
  File "C:\Users\kelly\AppData\Local\Programs\Python\Python312\Lib\http\client.py", line 300, in _read_status
    raise RemoteDisconnected("Remote end closed connection without"
urllib3.exceptions.ProtocolError: ('Connection aborted.', RemoteDisconnected('Remote end closed connection without response'))

During handling of the above exception, another exception occurred:

Traceback (most recent call last):
  File "c:\Users\kelly\Downloads\Python\Kroger\kroger-add-to-cart\kroger.py", line 65, in <module>
    product = get_product(upc, token)
              ^^^^^^^^^^^^^^^^^^^^^^^
  File "c:\Users\kelly\Downloads\Python\Kroger\kroger-add-to-cart\functions.py", line 131, in get_product
    product = requests.get(f"https://api.kroger.com/v1/products/{upc}", headers=headers, data=search)
              ^^^^^^^^^^^^^^^^^^^^^^^^^^^^^^^^^^^^^^^^^^^^^^^^^^^^^^^^^^^^^^^^^^^^^^^^^^^^^^^^^^^^^^^
  File "C:\Users\kelly\AppData\Local\Programs\Python\Python312\Lib\site-packages\requests\api.py", line 73, in get
    return request("get", url, params=params, **kwargs)
           ^^^^^^^^^^^^^^^^^^^^^^^^^^^^^^^^^^^^^^^^^^^^
  File "C:\Users\kelly\AppData\Local\Programs\Python\Python312\Lib\site-packages\requests\api.py", line 59, in request
    return session.request(method=method, url=url, **kwargs)
           ^^^^^^^^^^^^^^^^^^^^^^^^^^^^^^^^^^^^^^^^^^^^^^^^^
  File "C:\Users\kelly\AppData\Local\Programs\Python\Python312\Lib\site-packages\requests\sessions.py", line 589, in request
    resp = self.send(prep, **send_kwargs)
           ^^^^^^^^^^^^^^^^^^^^^^^^^^^^^^
  File "C:\Users\kelly\AppData\Local\Programs\Python\Python312\Lib\site-packages\requests\sessions.py", line 703, in send
    r = adapter.send(request, **kwargs)
        ^^^^^^^^^^^^^^^^^^^^^^^^^^^^^^^
  File "C:\Users\kelly\AppData\Local\Programs\Python\Python312\Lib\site-packages\requests\adapters.py", line 501, in send
    raise ConnectionError(err, request=request)
requests.exceptions.ConnectionError: ('Connection aborted.', RemoteDisconnected('Remote end closed connection without response'))
